Workbook
Name Event_ID: #REF!
Name Event_Name: #REF!
Name Export_Time_PT: #REF!
Name Prepared_By: #REF!
Name TEX_File: #REF!

Sheet README
A1: For CGS/NWS/Cal OES Use Only
A2: California Statewide manual FASTER Hand-Calculation Spreadsheet Approach to be used only by CGS, NWS, or Cal OES as a backup to the FASTER AWS online interface and the FASTER Desktop Application.
A12: To use this Excel spreadsheet, manually fill out the required fields (red text).
A14: Tab (1): Start by pasting TEX data as values.
A15: Tab (2): Paste ETSS py script data as values. This info may be important initial info to share.
A16: Tab (3): Enter NTWC forecast amplitude in cell 'F3" for the Brookings forecast location 'BKG'
A17: Tab (4): Contains Maritime amplitudes and thresholds.
A18: Tab (5): Contains all Evacuation and Maritime Playbook Recommendations; print this page as a pdf and distribute to Cal OES Seismic Hazards Duty Officer.

Sheet (1) Paste CA TEX Values
A1: site id | B1: siteStateName | C1: siteCode | D1: siteName | E1: predictedArrivalTime_PST_or_PDT | F1: predictedArrivalTime_plus_5hr_PST_or_PDT | G1: Lat_dd | H1: Long_dd | I1: predictedPosAmplitude_m | J1: predictedPosAmpUnc_m | K1: predictedDuration_hrs | L1: predictedArrivalTime_UTC | N1: For CGS/NWS/Cal OES Use Only
A2: 127 | B2: California | C2: MTR | D2: Mattole River | E2: 2026-02-01 22:40:00 PST | F2: 2026-02-02 03:40:00 PST | G2: 40.295 | H2: -124.356 | I2: 5.472996 | J2: 0.15 | K2: 15 | L2: 2026-02-02 06:40:00 UTC | N2: Instructions:
A3: 138 | B3: California | C3: LCS | D3: Lost Coast Shoreline | E3: 2026-02-01 22:45:00 PST | F3: 2026-02-02 03:45:00 PST | G3: 40.172 | H3: -124.239 | I3: 4.3506192 | J3: 0.13 | K3: 15 | L3: 2026-02-02 06:45:00 UTC | N3: Run the py script "Step_01_NTWC_Forecast_Amp_ArrivalTimes_V04.py" and paste only values here (grey box to the left ). If the formatting changes in the grey box, undo the paste and try again to only paste values so that there are no downstream effects.
A4: 141 | B4: California | C4: CPM | D4: Cape Mendocino | E4: 2026-02-01 22:45:00 PST | F4: 2026-02-02 03:45:00 PST | G4: 40.517 | H4: -124.4 | L4: 2026-02-02 06:45:00 UTC
A5: 147 | B5: California | C5: HBB | D5: Humboldt Bay | E5: 2026-02-01 22:50:00 PST | F5: 2026-02-02 03:50:00 PST | G5: 40.76 | H5: -124.227 | I5: 3.3840877 | J5: 0.09 | K5: 9 | L5: 2026-02-02 06:50:00 UTC
A6: 148 | B6: California | C6: MHL | D6: Mendo/Hum County Line | E6: 2026-02-01 22:50:00 PST | F6: 2026-02-02 03:50:00 PST | G6: 40.001 | H6: -124.035 | L6: 2026-02-02 06:50:00 UTC
A7: 149 | B7: California | C7: FBG | D7: Fort Bragg | E7: 2026-02-01 22:50:00 PST | F7: 2026-02-02 03:50:00 PST | G7: 39.428 | H7: -123.818 | I7: 3.2598899 | J7: 0.1 | K7: 9 | L7: 2026-02-02 06:50:00 UTC
A8: 150 | B8: California | C8: SSP | D8: South Spit | E8: 2026-02-01 22:50:00 PST | F8: 2026-02-02 03:50:00 PST | G8: 40.73 | H8: -124.25 | I8: 2.9651922 | J8: 0.08 | K8: 0 | L8: 2026-02-02 06:50:00 UTC
A9: 152 | B9: California | C9: CRE | D9: Crescent City | E9: 2026-02-01 22:50:00 PST | F9: 2026-02-02 03:50:00 PST | G9: 41.747 | H9: -124.183 | I9: 13.187217 | J9: 0.35 | K9: 30 | L9: 2026-02-02 06:50:00 UTC
A10: 155 | B10: California | C10: TEN | D10: Ten Mile River Beach | E10: 2026-02-01 22:50:00 PST | F10: 2026-02-02 03:50:00 PST | G10: 39.53 | H10: -123.78 | I10: 4.2192736 | J10: 0.15 | K10: 15 | L10: 2026-02-02 06:50:00 UTC
A11: 157 | B11: California | C11: MEN | D11: Mendocino | E11: 2026-02-01 22:50:00 PST | F11: 2026-02-02 03:50:00 PST | G11: 39.32 | H11: -123.82 | I11: 3.3675224 | J11: 0.09 | K11: 0 | L11: 2026-02-02 06:50:00 UTC
A12: 165 | B12: California | C12: EUR | D12: Eureka | E12: 2026-02-01 22:55:00 PST | F12: 2026-02-02 03:55:00 PST | G12: 40.8 | H12: -124.18 | I12: 2.8423485 | J12: 0.09 | K12: 9 | L12: 2026-02-02 06:55:00 UTC
A13: 172 | B13: California | C13: NSC | D13: North Spit coast | E13: 2026-02-01 22:55:00 PST | F13: 2026-02-02 03:55:00 PST | G13: 40.962 | H13: -124.132 | I13: 6.815402 | J13: 0.19 | K13: 20 | L13: 2026-02-02 06:55:00 UTC
A14: 176 | B14: California | C14: GUP | D14: Gualala River | E14: 2026-02-01 22:55:00 PST | F14: 2026-02-02 03:55:00 PST | G14: 38.768 | H14: -123.534 | L14: 2026-02-02 06:55:00 UTC
A15: 178 | B15: California | C15: ARN | D15: Arena Cove | E15: 2026-02-01 22:55:00 PST | F15: 2026-02-02 03:55:00 PST | G15: 38.915 | H15: -123.711 | I15: 5.1610826 | J15: 0.14 | K15: 15 | L15: 2026-02-02 06:55:00 UTC
A16: 179 | B16: California | C16: TND | D16: Trinidad | E16: 2026-02-01 22:55:00 PST | F16: 2026-02-02 03:55:00 PST | G16: 41.05 | H16: -124.13 | I16: 7.2664676 | J16: 0.21 | K16: 20 | L16: 2026-02-02 06:55:00 UTC
A17: 180 | B17: California | C17: ELK | D17: Elk | E17: 2026-02-01 22:55:00 PST | F17: 2026-02-02 03:55:00 PST | G17: 39.12 | H17: -123.72 | I17: 4.5071019 | J17: 0.12 | K17: 15 | L17: 2026-02-02 06:55:00 UTC
A18: 182 | B18: California | C18: KRM | D18: Klamath River Mouth | E18: 2026-02-01 23:00:00 PST | F18: 2026-02-02 04:00:00 PST | G18: 41.53 | H18: -124.08 | I18: 8.0583448 | J18: 0.21 | K18: 20 | L18: 2026-02-02 07:00:00 UTC
A19: 183 | B19: California | C19: HDL | D19: Humboldt/Del Norte Line | E19: 2026-02-01 23:00:00 PST | F19: 2026-02-02 04:00:00 PST | G19: 41.465 | H19: -124.066 | L19: 2026-02-02 07:00:00 UTC
A20: 184 | B20: California | C20: CAR | D20: Carmel | E20: 2026-02-01 23:05:00 PST | F20: 2026-02-02 04:05:00 PST | G20: 36.55 | H20: -121.93 | I20: 1.4182671 | J20: 0.04 | K20: 0 | L20: 2026-02-02 07:05:00 UTC
A21: 185 | B21: California | C21: SUR | D21: Point Sur | E21: 2026-02-01 23:10:00 PST | F21: 2026-02-02 04:10:00 PST | G21: 36.31 | H21: -121.9 | I21: 2.8616902 | J21: 0.07 | K21: 0 | L21: 2026-02-02 07:10:00 UTC
A22: 186 | B22: California | C22: DVN | D22: Davenport | E22: 2026-02-01 23:10:00 PST | F22: 2026-02-02 04:10:00 PST | G22: 37.015 | H22: -122.208 | L22: 2026-02-02 07:10:00 UTC
A23: 188 | B23: California | C23: REY | D23: Point Reyes | E23: 2026-02-01 23:10:00 PST | F23: 2026-02-02 04:10:00 PST | G23: 38 | H23: -123.033 | I23: 5.7961923 | J23: 0.16 | K23: 15 | L23: 2026-02-02 07:10:00 UTC
A24: 189 | B24: California | C24: RRM | D24: Russian River Mouth | E24: 2026-02-01 23:10:00 PST | F24: 2026-02-02 04:10:00 PST | G24: 38.449 | H24: -123.132 | I24: 5.2422945 | J24: 0.15 | K24: 15 | L24: 2026-02-02 07:10:00 UTC
A25: 190 | B25: California | C25: BBY | D25: Bodega Bay | E25: 2026-02-01 23:10:00 PST | F25: 2026-02-02 04:10:00 PST | G25: 38.3 | H25: -123.02 | I25: 3.5963077 | J25: 0.09 | K25: 9 | L25: 2026-02-02 07:10:00 UTC | N25: Make sure to paste all cells (including header info) into A1; see example screenshot below).
A26: 191 | B26: California | C26: PRB | D26: Point Reyes Beach | E26: 2026-02-01 23:10:00 PST | F26: 2026-02-02 04:10:00 PST | G26: 38.08 | H26: -122.98 | I26: 3.3688897 | J26: 0.09 | K26: 9 | L26: 2026-02-02 07:10:00 UTC
A27: 192 | B27: California | C27: MSL | D27: Moss Landing | E27: 2026-02-01 23:10:00 PST | F27: 2026-02-02 04:10:00 PST | G27: 36.804 | H27: -121.794 | I27: 2.0268696 | J27: 0.05 | K27: 0 | L27: 2026-02-02 07:10:00 UTC
A28: 193 | B28: California | C28: SCZ | D28: Santa Cruz | E28: 2026-02-01 23:15:00 PST | F28: 2026-02-02 04:15:00 PST | G28: 36.95 | H28: -122.03 | I28: 3.6779066 | J28: 0.11 | K28: 9 | L28: 2026-02-02 07:15:00 UTC
A29: 195 | B29: California | C29: MNT | D29: Monterey | E29: 2026-02-01 23:15:00 PST | F29: 2026-02-02 04:15:00 PST | G29: 36.605 | H29: -121.89 | I29: 2.4384179 | J29: 0.07 | K29: 0 | L29: 2026-02-02 07:15:00 UTC
A30: 199 | B30: California | C30: RDM | D30: Rio Del Mar | E30: 2026-02-01 23:20:00 PST | F30: 2026-02-02 04:20:00 PST | G30: 36.97 | H30: -121.92 | I30: 5.4415522 | J30: 0.14 | K30: 15 | L30: 2026-02-02 07:20:00 UTC
A31: 200 | B31: California | C31: RGP | D31: Ragged Point | E31: 2026-02-01 23:20:00 PST | F31: 2026-02-02 04:20:00 PST | G31: 35.798 | H31: -121.35 | L31: 2026-02-02 07:20:00 UTC
A32: 201 | B32: California | C32: PHA | D32: Platform Harvest | E32: 2026-02-01 23:20:00 PST | F32: 2026-02-02 04:20:00 PST | G32: 34.468 | H32: -120.673 | I32: 1.175447 | J32: 0.03 | K32: 0 | L32: 2026-02-02 07:20:00 UTC
A33: 202 | B33: California | C33: HMB | D33: Half Moon Bay | E33: 2026-02-01 23:20:00 PST | F33: 2026-02-02 04:20:00 PST | G33: 37.47 | H33: -122.45 | I33: 4.1623739 | J33: 0.14 | K33: 15 | L33: 2026-02-02 07:20:00 UTC
A34: 204 | B34: California | C34: BNS | D34: Bolinas | E34: 2026-02-01 23:25:00 PST | F34: 2026-02-02 04:25:00 PST | G34: 37.903 | H34: -122.686 | I34: 4.1648636 | J34: 0.13 | K34: 15 | L34: 2026-02-02 07:25:00 UTC
A35: 205 | B35: California | C35: BLN | D35: Bolinas Lagoon | E35: 2026-02-01 23:25:00 PST | F35: 2026-02-02 04:25:00 PST | G35: 37.908 | H35: -122.679 | I35: 3.7055747 | J35: 0.09 | K35: 9 | L35: 2026-02-02 07:25:00 UTC
A36: 207 | B36: California | C36: PAC | D36: Pacifica | E36: 2026-02-01 23:25:00 PST | F36: 2026-02-02 04:25:00 PST | G36: 37.63 | H36: -122.5 | I36: 5.4929657 | J36: 0.16 | K36: 15 | L36: 2026-02-02 07:25:00 UTC
A37: 208 | B37: California | C37: PCC | D37: Point Conception | E37: 2026-02-01 23:30:00 PST | F37: 2026-02-02 04:30:00 PST | G37: 34.449 | H37: -120.473 | L37: 2026-02-02 07:30:00 UTC
A38: 209 | B38: California | C38: STB | D38: Stinson Beach | E38: 2026-02-01 23:30:00 PST | F38: 2026-02-02 04:30:00 PST | G38: 37.895 | H38: -122.643 | I38: 3.5556809 | J38: 0.11 | K38: 9 | L38: 2026-02-02 07:30:00 UTC
A39: 210 | B39: California | C39: DIC | D39: Diablo Canyon | E39: 2026-02-01 23:30:00 PST | F39: 2026-02-02 04:30:00 PST | G39: 35.205 | H39: -120.858 | I39: 2.8865636 | J39: 0.1 | K39: 9 | L39: 2026-02-02 07:30:00 UTC
A40: 211 | B40: California | C40: MOR | D40: Morro Bay | E40: 2026-02-01 23:30:00 PST | F40: 2026-02-02 04:30:00 PST | G40: 35.37 | H40: -120.87 | I40: 4.2132085 | J40: 0.12 | K40: 15 | L40: 2026-02-02 07:30:00 UTC
...

Sheet (2) ETSS_Picks_by_FA_Locations
L1: For CGS/NWS/Cal OES Use Only
A2: INITIAL TSUNAMI RESPONSE DECISION SUPPORT INFORMATION | L2: Instructions:
A3: county | B3: site | C3: siteCode | D3: station_id | E3: ETA_Pacific | F3: ETA_plus_5h_Pacific | G3: max_tide_m_MSL | H3: max_tide_time_Pacific | I3: max_surge_m | J3: max_surge_time_Pacific | L3: Run the py script "Step_02_Export_Tab2_ETSS_Picks_v01.py" and paste only values here (grey box to the left ). If the formatting changes in the grey box, undo the paste and try again to only paste values so that there are no downstream effects.
A4: Alameda | B4: Fremont | C4: AVO | D4: 9414523 | E4: 2026-02-02 01:10 PST | F4: 2026-02-02 06:10 PST | G4: 0.9675 | H4: 2026-02-02 01:12 PST | I4: 0.0914 | J4: 2026-02-02 03:00 PST
A5: Alameda | B5: Hayward | C5: SCL | D5: 9414523 | E5: 2026-02-02 00:40 PST | F5: 2026-02-02 05:40 PST | G5: 0.9684 | H5: 2026-02-02 01:06 PST | I5: 0.0914 | J5: 2026-02-02 01:00 PST
A6: Alameda | B6: Alameda | C6: ALA | D6: 9414750 | E6: 2026-02-01 23:55 PST | F6: 2026-02-02 04:55 PST | G6: 0.7793 | H6: 2026-02-02 00:42 PST | I6: 0.061 | J6: 2026-02-02 00:00 PST
A7: Alameda | B7: Bayfarm Island Airport | C7: ALA | D7: 9414750 | E7: 2026-02-01 23:55 PST | F7: 2026-02-02 04:55 PST | G7: 0.7793 | H7: 2026-02-02 00:42 PST | I7: 0.061 | J7: 2026-02-02 00:00 PST
A8: Alameda | B8: Oakland Outer Harbor | C8: OOH | D8: 9414750 | E8: 2026-02-01 23:55 PST | F8: 2026-02-02 04:55 PST | G8: 0.7793 | H8: 2026-02-02 00:42 PST | I8: 0.061 | J8: 2026-02-02 00:00 PST
A9: Alameda | B9: San Leandro | C9: SCL | D9: 9414750 | E9: 2026-02-02 00:40 PST | F9: 2026-02-02 05:40 PST | G9: 0.7793 | H9: 2026-02-02 00:42 PST | I9: 0.061 | J9: 2026-02-02 01:00 PST
A10: Alameda | B10: San Lorenzo | C10: SCL | D10: 9414750 | E10: 2026-02-02 00:40 PST | F10: 2026-02-02 05:40 PST | G10: 0.7793 | H10: 2026-02-02 00:42 PST | I10: 0.061 | J10: 2026-02-02 01:00 PST
A11: Alameda | B11: Albany | C11: RID | D11: 9414863 | E11: 2026-02-01 23:50 PST | F11: 2026-02-02 04:50 PST | G11: 0.6912 | H11: 2026-02-02 00:48 PST | I11: 0.0914 | J11: 2026-02-02 01:00 PST
A12: Alameda | B12: Berkeley | C12: RID | D12: 9414863 | E12: 2026-02-01 23:50 PST | F12: 2026-02-02 04:50 PST | G12: 0.6912 | H12: 2026-02-02 00:48 PST | I12: 0.0914 | J12: 2026-02-02 01:00 PST
A13: Alameda | B13: Emeryville | C13: RID | D13: 9414863 | E13: 2026-02-01 23:50 PST | F13: 2026-02-02 04:50 PST | G13: 0.6912 | H13: 2026-02-02 00:48 PST | I13: 0.0914 | J13: 2026-02-02 01:00 PST
A14: Contra Costa | B14: North Richmond | C14: RID | D14: 9414863 | E14: 2026-02-01 23:50 PST | F14: 2026-02-02 04:50 PST | G14: 0.6912 | H14: 2026-02-02 00:48 PST | I14: 0.0914 | J14: 2026-02-02 01:00 PST
A15: Contra Costa | B15: Point Richmond | C15: RID | D15: 9414863 | E15: 2026-02-01 23:50 PST | F15: 2026-02-02 04:50 PST | G15: 0.6912 | H15: 2026-02-02 00:48 PST | I15: 0.0914 | J15: 2026-02-02 01:00 PST
... A24: Contra Costa | B24: Point Pinole | C24: MRE | D24: 9415102 | E24: 2026-02-02 00:30 PST | F24: 2026-02-02 05:30 PST | G24: 0.5701 | H24: 2026-02-02 02:12 PST | I24: 0.1219 | J24: 2026-02-02 01:00 PST
A25: Del Norte | B25: CA/OR border | C25: BKG | D25: 9419750 | E25: 2026-02-01 22:50 PST | F25: 2026-02-02 03:50 PST | G25: 0.8664 | H25: 2026-02-02 00:06 PST | I25: 0.0305 | J25: 2026-02-01 23:00 PST | L25: Make sure to paste all cells (including header info) into A1; see example screenshot below).
A26: Del Norte | B26: Smith River | C26: BKG | D26: 9419750 | E26: 2026-02-01 22:50 PST | F26: 2026-02-02 03:50 PST | G26: 0.8664 | H26: 2026-02-02 00:06 PST | I26: 0.0305 | J26: 2026-02-01 23:00 PST
A27: Del Norte | B27: Crescent City | C27: CRE | D27: 9419750 | E27: 2026-02-01 22:50 PST | F27: 2026-02-02 03:50 PST | G27: 0.8664 | H27: 2026-02-02 00:06 PST | I27: 0.0305 | J27: 2026-02-01 23:00 PST
A28: Del Norte | B28: Lagoon | C28: KRM | D28: 9419750 | E28: 2026-02-01 23:00 PST | F28: 2026-02-02 04:00 PST | G28: 0.8664 | H28: 2026-02-02 00:06 PST | I28: 0.0305 | J28: 2026-02-01 23:00 PST
A29: Del Norte | B29: Klamath | C29: KRM | D29: 9419750 | E29: 2026-02-01 23:00 PST | F29: 2026-02-02 04:00 PST | G29: 0.8664 | H29: 2026-02-02 00:06 PST | I29: 0.0305 | J29: 2026-02-01 23:00 PST
A30: Humboldt | B30: Arcata | C30: EUR | D30: 9418767 | E30: 2026-02-01 22:55 PST | F30: 2026-02-02 03:55 PST | G30: 0.7852 | H30: 2026-02-02 00:24 PST | I30: 0.061 | J30: 2026-02-02 03:00 PST
A31: Humboldt | B31: Eureka | C31: EUR | D31: 9418767 | E31: 2026-02-01 22:55 PST | F31: 2026-02-02 03:55 PST | G31: 0.7852 | H31: 2026-02-02 00:24 PST | I31: 0.061 | J31: 2026-02-02 03:00 PST
A32: Humboldt | B32: Humboldt Bay | C32: HBB | D32: 9418767 | E32: 2026-02-01 22:50 PST | F32: 2026-02-02 03:50 PST | G32: 0.7852 | H32: 2026-02-02 00:24 PST | I32: 0.061 | J32: 2026-02-02 03:00 PST
A33: Humboldt | B33: King Salmon | C33: HBB | D33: 9418767 | E33: 2026-02-01 22:50 PST | F33: 2026-02-02 03:50 PST | G33: 0.7852 | H33: 2026-02-02 00:24 PST | I33: 0.061 | J33: 2026-02-02 03:00 PST
A34: Humboldt | B34: Shelter Cove | C34: LCS | D34: 9418767 | E34: 2026-02-01 22:45 PST | F34: 2026-02-02 03:45 PST | G34: 0.7852 | H34: 2026-02-02 00:24 PST | I34: 0.061 | J34: 2026-02-02 03:00 PST
A35: Humboldt | B35: North Spit coast | C35: NSC | D35: 9418767 | E35: 2026-02-01 22:55 PST | F35: 2026-02-02 03:55 PST | G35: 0.7852 | H35: 2026-02-02 00:24 PST | I35: 0.061 | J35: 2026-02-02 03:00 PST
A36: Humboldt | B36: South Spit coast | C36: SSP | D36: 9418767 | E36: 2026-02-01 22:50 PST | F36: 2026-02-02 03:50 PST | G36: 0.7852 | H36: 2026-02-02 00:24 PST | I36: 0.061 | J36: 2026-02-02 03:00 PST
A37: Humboldt | B37: Ferndale | C37: SSP | D37: 9418767 | E37: 2026-02-01 22:50 PST | F37: 2026-02-02 03:50 PST | G37: 0.7852 | H37: 2026-02-02 00:24 PST | I37: 0.061 | J37: 2026-02-02 03:00 PST
... A195: Ventura | B195: Ventura Harbor | C195: VEN | D195: 9411340 | E195: 2026-02-02 00:05 PST | F195: 2026-02-02 05:05 PST | G195: 0.144 | H195: 2026-02-02 00:06 PST | I195: 0.2438 | J195: 2026-02-02 01:00 PST

Sheet (3) Calc Values by siteCode
A1: For CGS/NWS/Cal OES Use Only | N1: Red numbers = input real-time data
A2: County | B2: Coastal Community (QC Names) | C2: TEX_siteName | D2: TEX_siteCode (used to parse FA in TEX file) | E2: Closest NOAA Station (KEY for Xlookup) (NEED TO QC) | F2: Forecast Amplitude, given and projected (meters MSL) | G2: Max. Tidal Height within 5 hours of Tsunami ETA (meters MSL) | H2: Storm/ambient conditions peak in preceding 24-hours (meters MSL) | I2: Error in forecast amplitudes (30% of forecast amplitude; in meters) | J2: Anticipated tsunami height first 5 hours (meters MSL) | K2: Runup potential factor per location (applied if inudation expected) | L2: Runup potential per location | M2: Anticipated tsunami height first 5 hours, if inundation expected (meters MSL) | N2: NOAA Tide Gauge Name | O2: QC Check | P2: NOAA Tides & Currents Weblink
A3: Del Norte | B3: CA/OR border | C3: *NA | D3: BKG | E3: 9419750 | F3: 0.35 | G3: =_xlfn.XLOOKUP($B3,'(2) ETSS_Picks_by_FA_Locations'!$B$4:$B$195,'(2) ETSS_Picks_by_FA_Locations'!$G$4:$G$195,"ERROR",0,1) -> 0.8664 | H3: =_xlfn.XLOOKUP($B3,'(2) ETSS_Picks_by_FA_Locations'!$B$4:$B$195,'(2) ETSS_Picks_by_FA_Locations'!$I$4:$I$195,"ERROR",0,1) -> 0.0305 | I3: =0.3*(F3) -> 0.105 | J3: =SUM(F3:I3) -> 1.3519 | K3: 0.2 | L3: =K3*J3 -> 0.27038 | M3: =SUM(J3,L3) -> 1.62228 | N3: 9419750 | O3: =IF(E3=N3, "-", "ERROR") -> -
A4: Del Norte | B4: Smith River | C4: *NA | D4: BKG | E4: 9419750 | F4: =F3 -> 0.35 | G4: =_xlfn.XLOOKUP($B4,'(2) ETSS_Picks_by_FA_Locations'!$B$4:$B$195,'(2) ETSS_Picks_by_FA_Locations'!$G$4:$G$195,"ERROR",0,1) -> 0.8664 | H4: =_xlfn.XLOOKUP($B4,'(2) ETSS_Picks_by_FA_Locations'!$B$4:$B$195,'(2) ETSS_Picks_by_FA_Locations'!$I$4:$I$195,"ERROR",0,1) -> 0.0305 | I4: =0.3*(F4) -> 0.105 | J4: =SUM(F4:I4) -> 1.3519 | K4: 0.1 | L4: =K4*J4 -> 0.13519 | M4: =SUM(J4,L4) -> 1.48709 | N4: 9419750 | O4: =IF(E4=N4, "-", "ERROR") -> - | P4: Crescent City
A5: Del Norte | B5: Crescent City | C5: =_xlfn.XLOOKUP(D5,'(1) Paste CA TEX Values'!$C$2:$C$96,'(1) Paste CA TEX Values'!$D$2:$D$96,"ERROR",0,1) -> Crescent City | D5: CRE | E5: 9419750 | F5: =_xlfn.XLOOKUP($D5,'(1) Paste CA TEX Values'!$C$1:$C$96, '(1) Paste CA TEX Values'!$I$1:$I$96, "ERROR",0,1) -> 13.187217 | G5: =_xlfn.XLOOKUP($B5,'(2) ETSS_Picks_by_FA_Locations'!$B$4:$B$195,'(2) ETSS_Picks_by_FA_Locations'!$G$4:$G$195,"ERROR",0,1) -> 0.8664 | H5: =_xlfn.XLOOKUP($B5,'(2) ETSS_Picks_by_FA_Locations'!$B$4:$B$195,'(2) ETSS_Picks_by_FA_Locations'!$I$4:$I$195,"ERROR",0,1) -> 0.0305 | I5: =0.3*(F5) -> 3.956165 | J5: =SUM(F5:I5) -> 18.040282 | K5: 0.2 | L5: =K5*J5 -> 3.6080563 | M5: =SUM(J5,L5) -> 21.648338 | N5: 9419750 | O5: =IF(E5=N5, "-", "ERROR") -> - | P5: https://tidesandcurrents.noaa.gov/waterlevels.html?id=9419750&units=metric&timezone=LST/LDT&datum=MSL&interval=6&action=
A6: Del Norte | B6: Lagoon | C6: =_xlfn.XLOOKUP(D6,'(1) Paste CA TEX Values'!$C$2:$C$96,'(1) Paste CA TEX Values'!$D$2:$D$96,"ERROR",0,1) -> Klamath River Mouth | D6: KRM | E6: 9419750 | F6: =_xlfn.XLOOKUP($D6,'(1) Paste CA TEX Values'!$C$1:$C$96, '(1) Paste CA TEX Values'!$I$1:$I$96, "ERROR",0,1) -> 8.0583448 | G6: =_xlfn.XLOOKUP($B6,'(2) ETSS_Picks_by_FA_Locations'!$B$4:$B$195,'(2) ETSS_Picks_by_FA_Locations'!$G$4:$G$195,"ERROR",0,1) -> 0.8664 | H6: =_xlfn.XLOOKUP($B6,'(2) ETSS_Picks_by_FA_Locations'!$B$4:$B$195,'(2) ETSS_Picks_by_FA_Locations'!$I$4:$I$195,"ERROR",0,1) -> 0.0305 | I6: =0.3*(F6) -> 2.4175034 | J6: =SUM(F6:I6) -> 11.372748 | K6: 0.1 | L6: =K6*J6 -> 1.1372748 | M6: =SUM(J6,L6) -> 12.510023 | N6: 9419750 | O6: =IF(E6=N6, "-", "ERROR") -> -
A7: Del Norte | B7: Klamath | C7: =_xlfn.XLOOKUP(D7,'(1) Paste CA TEX Values'!$C$2:$C$96,'(1) Paste CA TEX Values'!$D$2:$D$96,"ERROR",0,1) -> Klamath River Mouth | D7: KRM | E7: 9419750 | F7: =_xlfn.XLOOKUP($D7,'(1) Paste CA TEX Values'!$C$1:$C$96, '(1) Paste CA TEX Values'!$I$1:$I$96, "ERROR",0,1) -> 8.0583448 | G7: =_xlfn.XLOOKUP($B7,'(2) ETSS_Picks_by_FA_Locations'!$B$4:$B$195,'(2) ETSS_Picks_by_FA_Locations'!$G$4:$G$195,"ERROR",0,1) -> 0.8664 | H7: =_xlfn.XLOOKUP($B7,'(2) ETSS_Picks_by_FA_Locations'!$B$4:$B$195,'(2) ETSS_Picks_by_FA_Locations'!$I$4:$I$195,"ERROR",0,1) -> 0.0305 | I7: =0.3*(F7) -> 2.4175034 | J7: =SUM(F7:I7) -> 11.372748 | K7: 0.1 | L7: =K7*J7 -> 1.1372748 | M7: =SUM(J7,L7) -> 12.510023 | N7: 9419750 | O7: =IF(E7=N7, "-", "ERROR") -> -
A8: Humboldt | B8: Orick-Redwood Cr. | C8: =_xlfn.XLOOKUP(D8,'(1) Paste CA TEX Values'!$C$2:$C$96,'(1) Paste CA TEX Values'!$D$2:$D$96,"ERROR",0,1) -> Trinidad | D8: TND | E8: 9418767 | F8: =_xlfn.XLOOKUP($D8,'(1) Paste CA TEX Values'!$C$1:$C$96, '(1) Paste CA TEX Values'!$I$1:$I$96, "ERROR",0,1) -> 7.2664676 | G8: =_xlfn.XLOOKUP($B8,'(2) ETSS_Picks_by_FA_Locations'!$B$4:$B$195,'(2) ETSS_Picks_by_FA_Locations'!$G$4:$G$195,"ERROR",0,1) -> 0.7852 | H8: =_xlfn.XLOOKUP($B8,'(2) ETSS_Picks_by_FA_Locations'!$B$4:$B$195,'(2) ETSS_Picks_by_FA_Locations'!$I$4:$I$195,"ERROR",0,1) -> 0.061 | I8: =0.3*(F8) -> 2.1799403 | J8: =SUM(F8:I8) -> 10.292608 | K8: 0.2 | L8: =K8*J8 -> 2.0585216 | M8: =SUM(J8,L8) -> 12.35113 | N8: 9418767 | O8: =IF(E8=N8, "-", "ERROR") -> -
A9: Humboldt | B9: Big Lagoon | C9: =_xlfn.XLOOKUP(D9,'(1) Paste CA TEX Values'!$C$2:$C$96,'(1) Paste CA TEX Values'!$D$2:$D$96,"ERROR",0,1) -> Trinidad | D9: TND | E9: 9418767 | F9: =_xlfn.XLOOKUP($D9,'(1) Paste CA TEX Values'!$C$1:$C$96, '(1) Paste CA TEX Values'!$I$1:$I$96, "ERROR",0,1) -> 7.2664676 | G9: =_xlfn.XLOOKUP($B9,'(2) ETSS_Picks_by_FA_Locations'!$B$4:$B$195,'(2) ETSS_Picks_by_FA_Locations'!$G$4:$G$195,"ERROR",0,1) -> 0.7852 | H9: =_xlfn.XLOOKUP($B9,'(2) ETSS_Picks_by_FA_Locations'!$B$4:$B$195,'(2) ETSS_Picks_by_FA_Locations'!$I$4:$I$195,"ERROR",0,1) -> 0.061 | I9: =0.3*(F9) -> 2.1799403 | J9: =SUM(F9:I9) -> 10.292608 | K9: 0.1 | L9: =K9*J9 -> 1.0292608 | M9: =SUM(J9,L9) -> 11.321869 | N9: 9418767 | O9: =IF(E9=N9, "-", "ERROR") -> -
A10: Humboldt | B10: Trinidad | C10: =_xlfn.XLOOKUP(D10,'(1) Paste CA TEX Values'!$C$2:$C$96,'(1) Paste CA TEX Values'!$D$2:$D$96,"ERROR",0,1) -> Trinidad | D10: TND | E10: 9418767 | F10: =_xlfn.XLOOKUP($D10,'(1) Paste CA TEX Values'!$C$1:$C$96, '(1) Paste CA TEX Values'!$I$1:$I$96, "ERROR",0,1) -> 7.2664676 | G10: =_xlfn.XLOOKUP($B10,'(2) ETSS_Picks_by_FA_Locations'!$B$4:$B$195,'(2) ETSS_Picks_by_FA_Locations'!$G$4:$G$195,"ERROR",0,1) -> 0.7852 | H10: =_xlfn.XLOOKUP($B10,'(2) ETSS_Picks_by_FA_Locations'!$B$4:$B$195,'(2) ETSS_Picks_by_FA_Locations'!$I$4:$I$195,"ERROR",0,1) -> 0.061 | I10: =0.3*(F10) -> 2.1799403 | J10: =SUM(F10:I10) -> 10.292608 | K10: 0.2 | L10: =K10*J10 -> 2.0585216 | M10: =SUM(J10,L10) -> 12.35113 | N10: 9418767 | O10: =IF(E10=N10, "-", "ERROR") -> - | P10: North Spit
A11: Humboldt | B11: North Spit coast | C11: =_xlfn.XLOOKUP(D11,'(1) Paste CA TEX Values'!$C$2:$C$96,'(1) Paste CA TEX Values'!$D$2:$D$96,"ERROR",0,1) -> North Spit coast | D11: NSC | E11: 9418767 | F11: =_xlfn.XLOOKUP($D11,'(1) Paste CA TEX Values'!$C$1:$C$96, '(1) Paste CA TEX Values'!$I$1:$I$96, "ERROR",0,1) -> 6.815402 | G11: =_xlfn.XLOOKUP($B11,'(2) ETSS_Picks_by_FA_Locations'!$B$4:$B$195,'(2) ETSS_Picks_by_FA_Locations'!$G$4:$G$195,"ERROR",0,1) -> 0.7852 | H11: =_xlfn.XLOOKUP($B11,'(2) ETSS_Picks_by_FA_Locations'!$B$4:$B$195,'(2) ETSS_Picks_by_FA_Locations'!$I$4:$I$195,"ERROR",0,1) -> 0.061 | I11: =0.3*(F11) -> 2.0446206 | J11: =SUM(F11:I11) -> 9.7062226 | K11: 0.1 | L11: =K11*J11 -> 0.97062226 | M11: =SUM(J11,L11) -> 10.676845 | N11: 9418767 | O11: =IF(E11=N11, "-", "ERROR") -> - | P11: https://tidesandcurrents.noaa.gov/waterlevels.html?id=9418767&units=metric&timezone=LST/LDT&datum=MSL&interval=6&action=
A12: Humboldt | B12: Arcata | C12: =_xlfn.XLOOKUP(D12,'(1) Paste CA TEX Values'!$C$2:$C$96,'(1) Paste CA TEX Values'!$D$2:$D$96,"ERROR",0,1) -> Eureka | D12: EUR | E12: 9418767 | F12: =_xlfn.XLOOKUP($D12,'(1) Paste CA TEX Values'!$C$1:$C$96, '(1) Paste CA TEX Values'!$I$1:$I$96, "ERROR",0,1) -> 2.8423485 | G12: =_xlfn.XLOOKUP($B12,'(2) ETSS_Picks_by_FA_Locations'!$B$4:$B$195,'(2) ETSS_Picks_by_FA_Locations'!$G$4:$G$195,"ERROR",0,1) -> 0.7852 | H12: =_xlfn.XLOOKUP($B12,'(2) ETSS_Picks_by_FA_Locations'!$B$4:$B$195,'(2) ETSS_Picks_by_FA_Locations'!$I$4:$I$195,"ERROR",0,1) -> 0.061 | I12: =0.3*(F12) -> 0.85270456 | J12: =SUM(F12:I12) -> 4.5412531 | K12: 0.1 | L12: =K12*J12 -> 0.45412531 | M12: =SUM(J12,L12) -> 4.9953784 | N12: 9418767 | O12: =IF(E12=N12, "-", "ERROR") -> -
A13: Humboldt | B13: Eureka | C13: =_xlfn.XLOOKUP(D13,'(1) Paste CA TEX Values'!$C$2:$C$96,'(1) Paste CA TEX Values'!$D$2:$D$96,"ERROR",0,1) -> Eureka | D13: EUR | E13: 9418767 | F13: =_xlfn.XLOOKUP($D13,'(1) Paste CA TEX Values'!$C$1:$C$96, '(1) Paste CA TEX Values'!$I$1:$I$96, "ERROR",0,1) -> 2.8423485 | G13: =_xlfn.XLOOKUP($B13,'(2) ETSS_Picks_by_FA_Locations'!$B$4:$B$195,'(2) ETSS_Picks_by_FA_Locations'!$G$4:$G$195,"ERROR",0,1) -> 0.7852 | H13: =_xlfn.XLOOKUP($B13,'(2) ETSS_Picks_by_FA_Locations'!$B$4:$B$195,'(2) ETSS_Picks_by_FA_Locations'!$I$4:$I$195,"ERROR",0,1) -> 0.061 | I13: =0.3*(F13) -> 0.85270456 | J13: =SUM(F13:I13) -> 4.5412531 | K13: 0.1 | L13: =K13*J13 -> 0.45412531 | M13: =SUM(J13,L13) -> 4.9953784 | N13: 9418767 | O13: =IF(E13=N13, "-", "ERROR") -> -
A14: Humboldt | B14: Humboldt Bay | C14: =_xlfn.XLOOKUP(D14,'(1) Paste CA TEX Values'!$C$2:$C$96,'(1) Paste CA TEX Values'!$D$2:$D$96,"ERROR",0,1) -> Humboldt Bay | D14: HBB | E14: 9418767 | F14: =_xlfn.XLOOKUP($D14,'(1) Paste CA TEX Values'!$C$1:$C$96, '(1) Paste CA TEX Values'!$I$1:$I$96, "ERROR",0,1) -> 3.3840877 | G14: =_xlfn.XLOOKUP($B14,'(2) ETSS_Picks_by_FA_Locations'!$B$4:$B$195,'(2) ETSS_Picks_by_FA_Locations'!$G$4:$G$195,"ERROR",0,1) -> 0.7852 | H14: =_xlfn.XLOOKUP($B14,'(2) ETSS_Picks_by_FA_Locations'!$B$4:$B$195,'(2) ETSS_Picks_by_FA_Locations'!$I$4:$I$195,"ERROR",0,1) -> 0.061 | I14: =0.3*(F14) -> 1.0152263 | J14: =SUM(F14:I14) -> 5.2455141 | K14: 0.1 | L14: =K14*J14 -> 0.52455141 | M14: =SUM(J14,L14) -> 5.7700655 | N14: 9418767 | O14: =IF(E14=N14, "-", "ERROR") -> -
A15: Humboldt | B15: King Salmon | C15: =_xlfn.XLOOKUP(D15,'(1) Paste CA TEX Values'!$C$2:$C$96,'(1) Paste CA TEX Values'!$D$2:$D$96,"ERROR",0,1) -> Humboldt Bay | D15: HBB | E15: 9418767 | F15: =_xlfn.XLOOKUP($D15,'(1) Paste CA TEX Values'!$C$1:$C$96, '(1) Paste CA TEX Values'!$I$1:$I$96, "ERROR",0,1) -> 3.3840877 | G15: =_xlfn.XLOOKUP($B15,'(2) ETSS_Picks_by_FA_Locations'!$B$4:$B$195,'(2) ETSS_Picks_by_FA_Locations'!$G$4:$G$195,"ERROR",0,1) -> 0.7852 | H15: =_xlfn.XLOOKUP($B15,'(2) ETSS_Picks_by_FA_Locations'!$B$4:$B$195,'(2) ETSS_Picks_by_FA_Locations'!$I$4:$I$195,"ERROR",0,1) -> 0.061 | I15: =0.3*(F15) -> 1.0152263 | J15: =SUM(F15:I15) -> 5.2455141 | K15: 0.1 | L15: =K15*J15 -> 0.52455141 | M15: =SUM(J15,L15) -> 5.7700655 | N15: 9418767 | O15: =IF(E15=N15, "-", "ERROR") -> -
A16: Humboldt | B16: South Spit coast | C16: =_xlfn.XLOOKUP(D16,'(1) Paste CA TEX Values'!$C$2:$C$96,'(1) Paste CA TEX Values'!$D$2:$D$96,"ERROR",0,1) -> South Spit | D16: SSP | E16: 9418767 | F16: =_xlfn.XLOOKUP($D16,'(1) Paste CA TEX Values'!$C$1:$C$96, '(1) Paste CA TEX Values'!$I$1:$I$96, "ERROR",0,1) -> 2.9651922 | G16: =_xlfn.XLOOKUP($B16,'(2) ETSS_Picks_by_FA_Locations'!$B$4:$B$195,'(2) ETSS_Picks_by_FA_Locations'!$G$4:$G$195,"ERROR",0,1) -> 0.7852 | H16: =_xlfn.XLOOKUP($B16,'(2) ETSS_Picks_by_FA_Locations'!$B$4:$B$195,'(2) ETSS_Picks_by_FA_Locations'!$I$4:$I$195,"ERROR",0,1) -> 0.061 | I16: =0.3*(F16) -> 0.88955767 | J16: =SUM(F16:I16) -> 4.7009499 | K16: 0.1 | L16: =K16*J16 -> 0.47009499 | M16: =SUM(J16,L16) -> 5.1710449 | N16: 9418767 | O16: =IF(E16=N16, "-", "ERROR") -> -
A17: Humboldt | B17: Ferndale | C17: =_xlfn.XLOOKUP(D17,'(1) Paste CA TEX Values'!$C$2:$C$96,'(1) Paste CA TEX Values'!$D$2:$D$96,"ERROR",0,1) -> South Spit | D17: SSP | E17: 9418767 | F17: =_xlfn.XLOOKUP($D17,'(1) Paste CA TEX Values'!$C$1:$C$96, '(1) Paste CA TEX Values'!$I$1:$I$96, "ERROR",0,1) -> 2.9651922 | G17: =_xlfn.XLOOKUP($B17,'(2) ETSS_Picks_by_FA_Locations'!$B$4:$B$195,'(2) ETSS_Picks_by_FA_Locations'!$G$4:$G$195,"ERROR",0,1) -> 0.7852 | H17: =_xlfn.XLOOKUP($B17,'(2) ETSS_Picks_by_FA_Locations'!$B$4:$B$195,'(2) ETSS_Picks_by_FA_Locations'!$I$4:$I$195,"ERROR",0,1) -> 0.061 | I17: =0.3*(F17) -> 0.88955767 | J17: =SUM(F17:I17) -> 4.7009499 | K17: 0.1 | L17: =K17*J17 -> 0.47009499 | M17: =SUM(J17,L17) -> 5.1710449 | N17: 9418767 | O17: =IF(E17=N17, "-", "ERROR") -> -
A18: Humboldt | B18: Shelter Cove | C18: =_xlfn.XLOOKUP(D18,'(1) Paste CA TEX Values'!$C$2:$C$96,'(1) Paste CA TEX Values'!$D$2:$D$96,"ERROR",0,1) -> Lost Coast Shoreline | D18: LCS | E18: 9418767 | F18: =_xlfn.XLOOKUP($D18,'(1) Paste CA TEX Values'!$C$1:$C$96, '(1) Paste CA TEX Values'!$I$1:$I$96, "ERROR",0,1) -> 4.3506192 | G18: =_xlfn.XLOOKUP($B18,'(2) ETSS_Picks_by_FA_Locations'!$B$4:$B$195,'(2) ETSS_Picks_by_FA_Locations'!$G$4:$G$195,"ERROR",0,1) -> 0.7852 | H18: =_xlfn.XLOOKUP($B18,'(2) ETSS_Picks_by_FA_Locations'!$B$4:$B$195,'(2) ETSS_Picks_by_FA_Locations'!$I$4:$I$195,"ERROR",0,1) -> 0.061 | I18: =0.3*(F18) -> 1.3051858 | J18: =SUM(F18:I18) -> 6.502005 | K18: 0.2 | L18: =K18*J18 -> 1.300401 | M18: =SUM(J18,L18) -> 7.802406 | N18: 9418767 | O18: =IF(E18=N18, "-", "ERROR") -> -
A19: Mendocino | B19: Cleone | C19: =_xlfn.XLOOKUP(D19,'(1) Paste CA TEX Values'!$C$2:$C$96,'(1) Paste CA TEX Values'!$D$2:$D$96,"ERROR",0,1) -> Ten Mile River Beach | D19: TEN | E19: 9416841 | F19: =_xlfn.XLOOKUP($D19,'(1) Paste CA TEX Values'!$C$1:$C$96, '(1) Paste CA TEX Values'!$I$1:$I$96, "ERROR",0,1) -> 4.2192736 | G19: =_xlfn.XLOOKUP($B19,'(2) ETSS_Picks_by_FA_Locations'!$B$4:$B$195,'(2) ETSS_Picks_by_FA_Locations'!$G$4:$G$195,"ERROR",0,1) -> 0.6133 | H19: =_xlfn.XLOOKUP($B19,'(2) ETSS_Picks_by_FA_Locations'!$B$4:$B$195,'(2) ETSS_Picks_by_FA_Locations'!$I$4:$I$195,"ERROR",0,1) -> 0.2134 | I19: =0.3*(F19) -> 1.2657821 | J19: =SUM(F19:I19) -> 6.3117557 | K19: 0.1 | L19: =K19*J19 -> 0.63117557 | M19: =SUM(J19,L19) -> 6.9429313 | N19: 9416841 | O19: =IF(E19=N19, "-", "ERROR") -> -
A20: Mendocino | B20: Ten Mile River | C20: =_xlfn.XLOOKUP(D20,'(1) Paste CA TEX Values'!$C$2:$C$96,'(1) Paste CA TEX Values'!$D$2:$D$96,"ERROR",0,1) -> Ten Mile River Beach | D20: TEN | E20: 9416841 | F20: =_xlfn.XLOOKUP($D20,'(1) Paste CA TEX Values'!$C$1:$C$96, '(1) Paste CA TEX Values'!$I$1:$I$96, "ERROR",0,1) -> 4.2192736 | G20: =_xlfn.XLOOKUP($B20,'(2) ETSS_Picks_by_FA_Locations'!$B$4:$B$195,'(2) ETSS_Picks_by_FA_Locations'!$G$4:$G$195,"ERROR",0,1) -> 0.6133 | H20: =_xlfn.XLOOKUP($B20,'(2) ETSS_Picks_by_FA_Locations'!$B$4:$B$195,'(2) ETSS_Picks_by_FA_Locations'!$I$4:$I$195,"ERROR",0,1) -> 0.2134 | I20: =0.3*(F20) -> 1.2657821 | J20: =SUM(F20:I20) -> 6.3117557 | K20: 0.1 | L20: =K20*J20 -> 0.63117557 | M20: =SUM(J20,L20) -> 6.9429313 | N20: 9416841 | O20: =IF(E20=N20, "-", "ERROR") -> -
A21: Mendocino | B21: Fort Bragg | C21: =_xlfn.XLOOKUP(D21,'(1) Paste CA TEX Values'!$C$2:$C$96,'(1) Paste CA TEX Values'!$D$2:$D$96,"ERROR",0,1) -> Fort Bragg | D21: FBG | E21: 9416841 | F21: =_xlfn.XLOOKUP($D21,'(1) Paste CA TEX Values'!$C$1:$C$96, '(1) Paste CA TEX Values'!$I$1:$I$96, "ERROR",0,1) -> 3.2598899 | G21: =_xlfn.XLOOKUP($B21,'(2) ETSS_Picks_by_FA_Locations'!$B$4:$B$195,'(2) ETSS_Picks_by_FA_Locations'!$G$4:$G$195,"ERROR",0,1) -> 0.6133 | H21: =_xlfn.XLOOKUP($B21,'(2) ETSS_Picks_by_FA_Locations'!$B$4:$B$195,'(2) ETSS_Picks_by_FA_Locations'!$I$4:$I$195,"ERROR",0,1) -> 0.2134 | I21: =0.3*(F21) -> 0.97796697 | J21: =SUM(F21:I21) -> 5.0645569 | K21: 0.2 | L21: =K21*J21 -> 1.0129114 | M21: =SUM(J21,L21) -> 6.0774683 | N21: 9416841 | O21: =IF(E21=N21, "-", "ERROR") -> -
A22: Mendocino | B22: Casper | C22: =_xlfn.XLOOKUP(D22,'(1) Paste CA TEX Values'!$C$2:$C$96,'(1) Paste CA TEX Values'!$D$2:$D$96,"ERROR",0,1) -> Mendocino | D22: MEN | E22: 9416841 | F22: =_xlfn.XLOOKUP($D22,'(1) Paste CA TEX Values'!$C$1:$C$96, '(1) Paste CA TEX Values'!$I$1:$I$96, "ERROR",0,1) -> 3.3675224 | G22: =_xlfn.XLOOKUP($B22,'(2) ETSS_Picks_by_FA_Locations'!$B$4:$B$195,'(2) ETSS_Picks_by_FA_Locations'!$G$4:$G$195,"ERROR",0,1) -> 0.6133 | H22: =_xlfn.XLOOKUP($B22,'(2) ETSS_Picks_by_FA_Locations'!$B$4:$B$195,'(2) ETSS_Picks_by_FA_Locations'!$I$4:$I$195,"ERROR",0,1) -> 0.2134 | I22: =0.3*(F22) -> 1.0102567 | J22: =SUM(F22:I22) -> 5.2044792 | K22: 0.2 | L22: =K22*J22 -> 1.0408958 | M22: =SUM(J22,L22) -> 6.245375 | N22: 9416841 | O22: =IF(E22=N22, "-", "ERROR") -> -
A23: Mendocino | B23: Mendocino | C23: =_xlfn.XLOOKUP(D23,'(1) Paste CA TEX Values'!$C$2:$C$96,'(1) Paste CA TEX Values'!$D$2:$D$96,"ERROR",0,1) -> Mendocino | D23: MEN | E23: 9416841 | F23: =_xlfn.XLOOKUP($D23,'(1) Paste CA TEX Values'!$C$1:$C$96, '(1) Paste CA TEX Values'!$I$1:$I$96, "ERROR",0,1) -> 3.3675224 | G23: =_xlfn.XLOOKUP($B23,'(2) ETSS_Picks_by_FA_Locations'!$B$4:$B$195,'(2) ETSS_Picks_by_FA_Locations'!$G$4:$G$195,"ERROR",0,1) -> 0.6133 | H23: =_xlfn.XLOOKUP($B23,'(2) ETSS_Picks_by_FA_Locations'!$B$4:$B$195,'(2) ETSS_Picks_by_FA_Locations'!$I$4:$I$195,"ERROR",0,1) -> 0.2134 | I23: =0.3*(F23) -> 1.0102567 | J23: =SUM(F23:I23) -> 5.2044792 | K23: 0.2 | L23: =K23*J23 -> 1.0408958 | M23: =SUM(J23,L23) -> 6.245375 | N23: 9416841 | O23: =IF(E23=N23, "-", "ERROR") -> -
A24: Mendocino | B24: Albion | C24: =_xlfn.XLOOKUP(D24,'(1) Paste CA TEX Values'!$C$2:$C$96,'(1) Paste CA TEX Values'!$D$2:$D$96,"ERROR",0,1) -> Mendocino | D24: MEN | E24: 9416841 | F24: =_xlfn.XLOOKUP($D24,'(1) Paste CA TEX Values'!$C$1:$C$96, '(1) Paste CA TEX Values'!$I$1:$I$96, "ERROR",0,1) -> 3.3675224 | G24: =_xlfn.XLOOKUP($B24,'(2) ETSS_Picks_by_FA_Locations'!$B$4:$B$195,'(2) ETSS_Picks_by_FA_Locations'!$G$4:$G$195,"ERROR",0,1) -> 0.6133 | H24: =_xlfn.XLOOKUP($B24,'(2) ETSS_Picks_by_FA_Locations'!$B$4:$B$195,'(2) ETSS_Picks_by_FA_Locations'!$I$4:$I$195,"ERROR",0,1) -> 0.2134 | I24: =0.3*(F24) -> 1.0102567 | J24: =SUM(F24:I24) -> 5.2044792 | K24: 0.2 | L24: =K24*J24 -> 1.0408958 | M24: =SUM(J24,L24) -> 6.245375 | N24: 9416841 | O24: =IF(E24=N24, "-", "ERROR") -> -
A25: Mendocino | B25: Elk | C25: =_xlfn.XLOOKUP(D25,'(1) Paste CA TEX Values'!$C$2:$C$96,'(1) Paste CA TEX Values'!$D$2:$D$96,"ERROR",0,1) -> Elk | D25: ELK | E25: 9416841 | F25: =_xlfn.XLOOKUP($D25,'(1) Paste CA TEX Values'!$C$1:$C$96, '(1) Paste CA TEX Values'!$I$1:$I$96, "ERROR",0,1) -> 4.5071019 | G25: =_xlfn.XLOOKUP($B25,'(2) ETSS_Picks_by_FA_Locations'!$B$4:$B$195,'(2) ETSS_Picks_by_FA_Locations'!$G$4:$G$195,"ERROR",0,1) -> 0.6133 | H25: =_xlfn.XLOOKUP($B25,'(2) ETSS_Picks_by_FA_Locations'!$B$4:$B$195,'(2) ETSS_Picks_by_FA_Locations'!$I$4:$I$195,"ERROR",0,1) -> 0.2134 | I25: =0.3*(F25) -> 1.3521306 | J25: =SUM(F25:I25) -> 6.6859324 | K25: 0.1 | L25: =K25*J25 -> 0.66859324 | M25: =SUM(J25,L25) -> 7.3545257 | N25: 9416841 | O25: =IF(E25=N25, "-", "ERROR") -> - | P25: Area Cove
A26: Mendocino | B26: Point Arena | C26: =_xlfn.XLOOKUP(D26,'(1) Paste CA TEX Values'!$C$2:$C$96,'(1) Paste CA TEX Values'!$D$2:$D$96,"ERROR",0,1) -> Arena Cove | D26: ARN | E26: 9416841 | F26: =_xlfn.XLOOKUP($D26,'(1) Paste CA TEX Values'!$C$1:$C$96, '(1) Paste CA TEX Values'!$I$1:$I$96, "ERROR",0,1) -> 5.1610826 | G26: =_xlfn.XLOOKUP($B26,'(2) ETSS_Picks_by_FA_Locations'!$B$4:$B$195,'(2) ETSS_Picks_by_FA_Locations'!$G$4:$G$195,"ERROR",0,1) -> 0.6133 | H26: =_xlfn.XLOOKUP($B26,'(2) ETSS_Picks_by_FA_Locations'!$B$4:$B$195,'(2) ETSS_Picks_by_FA_Locations'!$I$4:$I$195,"ERROR",0,1) -> 0.2134 | I26: =0.3*(F26) -> 1.5483248 | J26: =SUM(F26:I26) -> 7.5361074 | K26: 0.2 | L26: =K26*J26 -> 1.5072215 | M26: =SUM(J26,L26) -> 9.0433288 | N26: 9416841 | O26: =IF(E26=N26, "-", "ERROR") -> - | P26: https://tidesandcurrents.noaa.gov/waterlevels.html?id=9416841&units=metric&timezone=LST/LDT&datum=MSL&interval=6&action=
A27: Mendocino | B27: Anchor Bay | C27: =_xlfn.XLOOKUP(D27,'(1) Paste CA TEX Values'!$C$2:$C$96,'(1) Paste CA TEX Values'!$D$2:$D$96,"ERROR",0,1) -> Arena Cove | D27: ARN | E27: 9416841 | F27: =_xlfn.XLOOKUP($D27,'(1) Paste CA TEX Values'!$C$1:$C$96, '(1) Paste CA TEX Values'!$I$1:$I$96, "ERROR",0,1) -> 5.1610826 | G27: =_xlfn.XLOOKUP($B27,'(2) ETSS_Picks_by_FA_Locations'!$B$4:$B$195,'(2) ETSS_Picks_by_FA_Locations'!$G$4:$G$195,"ERROR",0,1) -> 0.6133 | H27: =_xlfn.XLOOKUP($B27,'(2) ETSS_Picks_by_FA_Locations'!$B$4:$B$195,'(2) ETSS_Picks_by_FA_Locations'!$I$4:$I$195,"ERROR",0,1) -> 0.2134 | I27: =0.3*(F27) -> 1.5483248 | J27: =SUM(F27:I27) -> 7.5361074 | K27: 0.1 | L27: =K27*J27 -> 0.75361074 | M27: =SUM(J27,L27) -> 8.2897181 | N27: 9416841 | O27: =IF(E27=N27, "-", "ERROR") -> -
A28: Sonoma | B28: Sea Ranch | C28: =_xlfn.XLOOKUP(D28,'(1) Paste CA TEX Values'!$C$2:$C$96,'(1) Paste CA TEX Values'!$D$2:$D$96,"ERROR",0,1) -> Russian River Mouth | D28: RRM | E28: 9415020 | F28: =_xlfn.XLOOKUP($D28,'(1) Paste CA TEX Values'!$C$1:$C$96, '(1) Paste CA TEX Values'!$I$1:$I$96, "ERROR",0,1) -> 5.2422945 | G28: =_xlfn.XLOOKUP($B28,'(2) ETSS_Picks_by_FA_Locations'!$B$4:$B$195,'(2) ETSS_Picks_by_FA_Locations'!$G$4:$G$195,"ERROR",0,1) -> 0.5975 | H28: =_xlfn.XLOOKUP($B28,'(2) ETSS_Picks_by_FA_Locations'!$B$4:$B$195,'(2) ETSS_Picks_by_FA_Locations'!$I$4:$I$195,"ERROR",0,1) -> 0.061 | I28: =0.3*(F28) -> 1.5726884 | J28: =SUM(F28:I28) -> 7.4734829 | K28: 0.1 | L28: =K28*J28 -> 0.74734829 | M28: =SUM(J28,L28) -> 8.2208312 | N28: 9415020 | O28: =IF(E28=N28, "-", "ERROR") -> -
A29: Sonoma | B29: Timber Cove | C29: =_xlfn.XLOOKUP(D29,'(1) Paste CA TEX Values'!$C$2:$C$96,'(1) Paste CA TEX Values'!$D$2:$D$96,"ERROR",0,1) -> Russian River Mouth | D29: RRM | E29: 9415020 | F29: =_xlfn.XLOOKUP($D29,'(1) Paste CA TEX Values'!$C$1:$C$96, '(1) Paste CA TEX Values'!$I$1:$I$96, "ERROR",0,1) -> 5.2422945 | G29: =_xlfn.XLOOKUP($B29,'(2) ETSS_Picks_by_FA_Locations'!$B$4:$B$195,'(2) ETSS_Picks_by_FA_Locations'!$G$4:$G$195,"ERROR",0,1) -> 0.5975 | H29: =_xlfn.XLOOKUP($B29,'(2) ETSS_Picks_by_FA_Locations'!$B$4:$B$195,'(2) ETSS_Picks_by_FA_Locations'!$I$4:$I$195,"ERROR",0,1) -> 0.061 | I29: =0.3*(F29) -> 1.5726884 | J29: =SUM(F29:I29) -> 7.4734829 | K29: 0.1 | L29: =K29*J29 -> 0.74734829 | M29: =SUM(J29,L29) -> 8.2208312 | N29: 9415020 | O29: =IF(E29=N29, "-", "ERROR") -> -
A30: Sonoma | B30: Fort Ross | C30: =_xlfn.XLOOKUP(D30,'(1) Paste CA TEX Values'!$C$2:$C$96,'(1) Paste CA TEX Values'!$D$2:$D$96,"ERROR",0,1) -> Russian River Mouth | D30: RRM | E30: 9415020 | F30: =_xlfn.XLOOKUP($D30,'(1) Paste CA TEX Values'!$C$1:$C$96, '(1) Paste CA TEX Values'!$I$1:$I$96, "ERROR",0,1) -> 5.2422945 | G30: =_xlfn.XLOOKUP($B30,'(2) ETSS_Picks_by_FA_Locations'!$B$4:$B$195,'(2) ETSS_Picks_by_FA_Locations'!$G$4:$G$195,"ERROR",0,1) -> 0.5975 | H30: =_xlfn.XLOOKUP($B30,'(2) ETSS_Picks_by_FA_Locations'!$B$4:$B$195,'(2) ETSS_Picks_by_FA_Locations'!$I$4:$I$195,"ERROR",0,1) -> 0.061 | I30: =0.3*(F30) -> 1.5726884 | J30: =SUM(F30:I30) -> 7.4734829 | K30: 0.1 | L30: =K30*J30 -> 0.74734829 | M30: =SUM(J30,L30) -> 8.2208312 | N30: 9415020 | O30: =IF(E30=N30, "-", "ERROR") -> -
A31: Sonoma | B31: Jenner-Russian River | C31: =_xlfn.XLOOKUP(D31,'(1) Paste CA TEX Values'!$C$2:$C$96,'(1) Paste CA TEX Values'!$D$2:$D$96,"ERROR",0,1) -> Russian River Mouth | D31: RRM | E31: 9415020 | F31: =_xlfn.XLOOKUP($D31,'(1) Paste CA TEX Values'!$C$1:$C$96, '(1) Paste CA TEX Values'!$I$1:$I$96, "ERROR",0,1) -> 5.2422945 | G31: =_xlfn.XLOOKUP($B31,'(2) ETSS_Picks_by_FA_Locations'!$B$4:$B$195,'(2) ETSS_Picks_by_FA_Locations'!$G$4:$G$195,"ERROR",0,1) -> 0.5975 | H31: =_xlfn.XLOOKUP($B31,'(2) ETSS_Picks_by_FA_Locations'!$B$4:$B$195,'(2) ETSS_Picks_by_FA_Locations'!$I$4:$I$195,"ERROR",0,1) -> 0.061 | I31: =0.3*(F31) -> 1.5726884 | J31: =SUM(F31:I31) -> 7.4734829 | K31: 0.1 | L31: =K31*J31 -> 0.74734829 | M31: =SUM(J31,L31) -> 8.2208312 | N31: 9415020 | O31: =IF(E31=N31, "-", "ERROR") -> -
A32: Sonoma | B32: Salmon Creek | C32: =_xlfn.XLOOKUP(D32,'(1) Paste CA TEX Values'!$C$2:$C$96,'(1) Paste CA TEX Values'!$D$2:$D$96,"ERROR",0,1) -> Russian River Mouth | D32: RRM | E32: 9415020 | F32: =_xlfn.XLOOKUP($D32,'(1) Paste CA TEX Values'!$C$1:$C$96, '(1) Paste CA TEX Values'!$I$1:$I$96, "ERROR",0,1) -> 5.2422945 | G32: =_xlfn.XLOOKUP($B32,'(2) ETSS_Picks_by_FA_Locations'!$B$4:$B$195,'(2) ETSS_Picks_by_FA_Locations'!$G$4:$G$195,"ERROR",0,1) -> 0.5975 | H32: =_xlfn.XLOOKUP($B32,'(2) ETSS_Picks_by_FA_Locations'!$B$4:$B$195,'(2) ETSS_Picks_by_FA_Locations'!$I$4:$I$195,"ERROR",0,1) -> 0.061 | I32: =0.3*(F32) -> 1.5726884 | J32: =SUM(F32:I32) -> 7.4734829 | K32: 0.2 | L32: =K32*J32 -> 1.4946966 | M32: =SUM(J32,L32) -> 8.9681795 | N32: 9415020 | O32: =IF(E32=N32, "-", "ERROR") -> -
A33: Sonoma | B33: Bodega Bay | C33: =_xlfn.XLOOKUP(D33,'(1) Paste CA TEX Values'!$C$2:$C$96,'(1) Paste CA TEX Values'!$D$2:$D$96,"ERROR",0,1) -> Bodega Bay | D33: BBY | E33: 9415020 | F33: =_xlfn.XLOOKUP($D33,'(1) Paste CA TEX Values'!$C$1:$C$96, '(1) Paste CA TEX Values'!$I$1:$I$96, "ERROR",0,1) -> 3.5963077 | G33: =_xlfn.XLOOKUP($B33,'(2) ETSS_Picks_by_FA_Locations'!$B$4:$B$195,'(2) ETSS_Picks_by_FA_Locations'!$G$4:$G$195,"ERROR",0,1) -> 0.5975 | H33: =_xlfn.XLOOKUP($B33,'(2) ETSS_Picks_by_FA_Locations'!$B$4:$B$195,'(2) ETSS_Picks_by_FA_Locations'!$I$4:$I$195,"ERROR",0,1) -> 0.061 | I33: =0.3*(F33) -> 1.0788923 | J33: =SUM(F33:I33) -> 5.3337 | K33: 0.1 | L33: =K33*J33 -> 0.53337 | M33: =SUM(J33,L33) -> 5.86707 | N33: 9415020 | O33: =IF(E33=N33, "-", "ERROR") -> -
A34: Sonoma | B34: Sears Point-Petaluma Valley | C34: =_xlfn.XLOOKUP(D34,'(1) Paste CA TEX Values'!$C$2:$C$96,'(1) Paste CA TEX Values'!$D$2:$D$96,"ERROR",0,1) -> Mare Island | D34: MRE | E34: 9414863 | F34: =_xlfn.XLOOKUP($D34,'(1) Paste CA TEX Values'!$C$1:$C$96, '(1) Paste CA TEX Values'!$I$1:$I$96, "ERROR",0,1) -> 2.4200194 | G34: =_xlfn.XLOOKUP($B34,'(2) ETSS_Picks_by_FA_Locations'!$B$4:$B$195,'(2) ETSS_Picks_by_FA_Locations'!$G$4:$G$195,"ERROR",0,1) -> 0.6912 | H34: =_xlfn.XLOOKUP($B34,'(2) ETSS_Picks_by_FA_Locations'!$B$4:$B$195,'(2) ETSS_Picks_by_FA_Locations'!$I$4:$I$195,"ERROR",0,1) -> 0.0914 | I34: =0.3*(F34) -> 0.72600581 | J34: =SUM(F34:I34) -> 3.9286252 | K34: 0 | L34: =K34*J34 -> 0 | M34: =SUM(J34,L34) -> 3.9286252 | N34: 9414863 | O34: =IF(E34=N34, "-", "ERROR") -> - | P34: Richmond
A35: Marin | B35: Dillons Beach | C35: =_xlfn.XLOOKUP(D35,'(1) Paste CA TEX Values'!$C$2:$C$96,'(1) Paste CA TEX Values'!$D$2:$D$96,"ERROR",0,1) -> Point Reyes | D35: REY | E35: 9415020 | F35: =_xlfn.XLOOKUP($D35,'(1) Paste CA TEX Values'!$C$1:$C$96, '(1) Paste CA TEX Values'!$I$1:$I$96, "ERROR",0,1) -> 5.7961923 | G35: =_xlfn.XLOOKUP($B35,'(2) ETSS_Picks_by_FA_Locations'!$B$4:$B$195,'(2) ETSS_Picks_by_FA_Locations'!$G$4:$G$195,"ERROR",0,1) -> 0.5975 | H35: =_xlfn.XLOOKUP($B35,'(2) ETSS_Picks_by_FA_Locations'!$B$4:$B$195,'(2) ETSS_Picks_by_FA_Locations'!$I$4:$I$195,"ERROR",0,1) -> 0.061 | I35: =0.3*(F35) -> 1.7388577 | J35: =SUM(F35:I35) -> 8.19355 | K35: 0.1 | L35: =K35*J35 -> 0.819355 | M35: =SUM(J35,L35) -> 9.0129051 | N35: 9415020 | O35: =IF(E35=N35, "-", "ERROR") -> - | P35: Point Reyes
A36: Marin | B36: Point Reyes | C36: =_xlfn.XLOOKUP(D36,'(1) Paste CA TEX Values'!$C$2:$C$96,'(1) Paste CA TEX Values'!$D$2:$D$96,"ERROR",0,1) -> Point Reyes | D36: REY | E36: 9415020 | F36: =_xlfn.XLOOKUP($D36,'(1) Paste CA TEX Values'!$C$1:$C$96, '(1) Paste CA TEX Values'!$I$1:$I$96, "ERROR",0,1) -> 5.7961923 | G36: =_xlfn.XLOOKUP($B36,'(2) ETSS_Picks_by_FA_Locations'!$B$4:$B$195,'(2) ETSS_Picks_by_FA_Locations'!$G$4:$G$195,"ERROR",0,1) -> 0.5975 | H36: =_xlfn.XLOOKUP($B36,'(2) ETSS_Picks_by_FA_Locations'!$B$4:$B$195,'(2) ETSS_Picks_by_FA_Locations'!$I$4:$I$195,"ERROR",0,1) -> 0.061 | I36: =0.3*(F36) -> 1.7388577 | J36: =SUM(F36:I36) -> 8.19355 | K36: 0.1 | L36: =K36*J36 -> 0.819355 | M36: =SUM(J36,L36) -> 9.0129051 | N36: 9415020 | O36: =IF(E36=N36, "-", "ERROR") -> - | P36: https://tidesandcurrents.noaa.gov/waterlevels.html?id=9415020&units=metric&timezone=LST/LDT&datum=MSL&interval=6&action=
A37: Marin | B37: Bolinas | C37: =_xlfn.XLOOKUP(D37,'(1) Paste CA TEX Values'!$C$2:$C$96,'(1) Paste CA TEX Values'!$D$2:$D$96,"ERROR",0,1) -> Bolinas | D37: BNS | E37: 9415020 | F37: =_xlfn.XLOOKUP($D37,'(1) Paste CA TEX Values'!$C$1:$C$96, '(1) Paste CA TEX Values'!$I$1:$I$96, "ERROR",0,1) -> 4.1648636 | G37: =_xlfn.XLOOKUP($B37,'(2) ETSS_Picks_by_FA_Locations'!$B$4:$B$195,'(2) ETSS_Picks_by_FA_Locations'!$G$4:$G$195,"ERROR",0,1) -> 0.5975 | H37: =_xlfn.XLOOKUP($B37,'(2) ETSS_Picks_by_FA_Locations'!$B$4:$B$195,'(2) ETSS_Picks_by_FA_Locations'!$I$4:$I$195,"ERROR",0,1) -> 0.061 | I37: =0.3*(F37) -> 1.2494591 | J37: =SUM(F37:I37) -> 6.0728227 | K37: 0.1 | L37: =K37*J37 -> 0.60728227 | M37: =SUM(J37,L37) -> 6.6801049 | N37: 9415020 | O37: =IF(E37=N37, "-", "ERROR") -> -
A38: Marin | B38: Stinson Beach | C38: =_xlfn.XLOOKUP(D38,'(1) Paste CA TEX Values'!$C$2:$C$96,'(1) Paste CA TEX Values'!$D$2:$D$96,"ERROR",0,1) -> Stinson Beach | D38: STB | E38: 9415020 | F38: =_xlfn.XLOOKUP($D38,'(1) Paste CA TEX Values'!$C$1:$C$96, '(1) Paste CA TEX Values'!$I$1:$I$96, "ERROR",0,1) -> 3.5556809 | G38: =_xlfn.XLOOKUP($B38,'(2) ETSS_Picks_by_FA_Locations'!$B$4:$B$195,'(2) ETSS_Picks_by_FA_Locations'!$G$4:$G$195,"ERROR",0,1) -> 0.5975 | H38: =_xlfn.XLOOKUP($B38,'(2) ETSS_Picks_by_FA_Locations'!$B$4:$B$195,'(2) ETSS_Picks_by_FA_Locations'!$I$4:$I$195,"ERROR",0,1) -> 0.061 | I38: =0.3*(F38) -> 1.0667043 | J38: =SUM(F38:I38) -> 5.2808852 | K38: 0.1 | L38: =K38*J38 -> 0.52808852 | M38: =SUM(J38,L38) -> 5.8089737 | N38: 9415020 | O38: =IF(E38=N38, "-", "ERROR") -> -
A39: Marin | B39: Muir Beach | C39: =_xlfn.XLOOKUP(D39,'(1) Paste CA TEX Values'!$C$2:$C$96,'(1) Paste CA TEX Values'!$D$2:$D$96,"ERROR",0,1) -> Bolinas | D39: BNS | E39: 9415020 | F39: =_xlfn.XLOOKUP($D39,'(1) Paste CA TEX Values'!$C$1:$C$96, '(1) Paste CA TEX Values'!$I$1:$I$96, "ERROR",0,1) -> 4.1648636 | G39: =_xlfn.XLOOKUP($B39,'(2) ETSS_Picks_by_FA_Locations'!$B$4:$B$195,'(2) ETSS_Picks_by_FA_Locations'!$G$4:$G$195,"ERROR",0,1) -> 0.5975 | H39: =_xlfn.XLOOKUP($B39,'(2) ETSS_Picks_by_FA_Locations'!$B$4:$B$195,'(2) ETSS_Picks_by_FA_Locations'!$I$4:$I$195,"ERROR",0,1) -> 0.061 | I39: =0.3*(F39) -> 1.2494591 | J39: =SUM(F39:I39) -> 6.0728227 | K39: 0.1 | L39: =K39*J39 -> 0.60728227 | M39: =SUM(J39,L39) -> 6.6801049 | N39: 9415020 | O39: =IF(E39=N39, "-", "ERROR") -> -
A40: Marin | B40: Rodeo Cove | C40: =_xlfn.XLOOKUP(D40,'(1) Paste CA TEX Values'!$C$2:$C$96,'(1) Paste CA TEX Values'!$D$2:$D$96,"ERROR",0,1) -> Bolinas | D40: BNS | E40: 9415020 | F40: =_xlfn.XLOOKUP($D40,'(1) Paste CA TEX Values'!$C$1:$C$96, '(1) Paste CA TEX Values'!$I$1:$I$96, "ERROR",0,1) -> 4.1648636 | G40: =_xlfn.XLOOKUP($B40,'(2) ETSS_Picks_by_FA_Locations'!$B$4:$B$195,'(2) ETSS_Picks_by_FA_Locations'!$G$4:$G$195,"ERROR",0,1) -> 0.5975 | H40: =_xlfn.XLOOKUP($B40,'(2) ETSS_Picks_by_FA_Locations'!$B$4:$B$195,'(2) ETSS_Picks_by_FA_Locations'!$I$4:$I$195,"ERROR",0,1) -> 0.061 | I40: =0.3*(F40) -> 1.2494591 | J40: =SUM(F40:I40) -> 6.0728227 | K40: 0.1 | L40: =K40*J40 -> 0.60728227 | M40: =SUM(J40,L40) -> 6.6801049 | N40: 9415020 | O40: =IF(E40=N40, "-", "ERROR") -> -
...

Sheet (4) Maritime Thresholds
D1: For CGS/NWS/Cal OES Use Only
A2: Maritime Playbook ID | B2: Maritime Location | C2: QC Location Names | D2: County | E2: stationID (used QC closest NOAA station to Maritime site) | F2: *TEX_siteCode* (key ID for FA value) | G2: Text_siteName | H2: Maritime Communities Playbook Guidance Plans (Ports, Harbors, and Marinas) | I2: Recommended MINIMUM Maritime Tsunami Response Plan, based on Forecast Tsunami Amplitude | J2: TEX FA (m MSL) | K2: Plan A | L2: Plan B | M2: Plan C | N2: Plan D | O2: Plan E | P2: Plan F
A3: C01-DN-M01 | B3: Crescent City | C3: =IF(H3=B3, "-", "ERROR") -> ERROR | D3: Del Norte | E3: 9419750 | F3: CRE | G3: =_xlfn.XLOOKUP($F3,'(1) Paste CA TEX Values'!$C$1:$C$96,'(1) Paste CA TEX Values'!$D$1:$D$96,"ERROR",0,1) -> Crescent City | H3: Crescent City Harbor | I3: =IF($J3<K3,"Forecast Amplitude below NTWC Advisory Threshold, refer to Evacuation Playbook",IF(AND($J3>=K3,$J3<L3),"Maritime Response Plan A",IF(AND($J3>=L3,$J3<M3),"Maritime Response Plan B",IF(AND($J3>=M3,$J3<N3),"Maritime Response Plan C",IF(AND($J3>=N3,$J3<O3),"Maritime Response Plan D",IF(AND($J3>=O3,$J3<P3),"Maritime Response Plan E","Maritime Response Plan F")))))) -> Maritime Response Plan E | J3: =_xlfn.XLOOKUP($F3,'(1) Paste CA TEX Values'!$C$1:$C$96,'(1) Paste CA TEX Values'!$I$1:$I$96,"ERROR",0,1) -> 13.187217 | K3: 0.3 | L3: 0.65 | M3: 0.95 | N3: 1.85 | O3: 2.55 | P3: NA
A4: C02-HUM-M01 | B4: Humboldt | C4: =IF(H4=B4, "-", "ERROR") -> ERROR | D4: Humboldt | E4: 9418767 | F4: HBB | G4: =_xlfn.XLOOKUP($F4,'(1) Paste CA TEX Values'!$C$1:$C$96,'(1) Paste CA TEX Values'!$D$1:$D$96,"ERROR",0,1) -> Humboldt Bay | H4: Humboldt Bay | I4: =IF($J4<K4,"Forecast Amplitude below NTWC Advisory Threshold, refer to Evacuation Playbook",IF(AND($J4>=K4,$J4<L4),"Maritime Response Plan A",IF(AND($J4>=L4,$J4<M4),"Maritime Response Plan B",IF(AND($J4>=M4,$J4<N4),"Maritime Response Plan C",IF(AND($J4>=N4,$J4<O4),"Maritime Response Plan D",IF(AND($J4>=O4,$J4<P4),"Maritime Response Plan E","Maritime Response Plan F")))))) -> Maritime Response Plan E | J4: =_xlfn.XLOOKUP($F4,'(1) Paste CA TEX Values'!$C$1:$C$96,'(1) Paste CA TEX Values'!$I$1:$I$96,"ERROR",0,1) -> 3.3840877 | K4: 0.3 | L4: 0.45 | M4: 0.85 | N4: 1.05 | O4: 1.25 | P4: NA
A5: C03-MEN-M01 | B5: Noyo River-Fort Bragg | C5: =IF(H5=B5, "-", "ERROR") -> ERROR | D5: Mendocino | E5: 9416841 | F5: FBG | G5: =_xlfn.XLOOKUP($F5,'(1) Paste CA TEX Values'!$C$1:$C$96,'(1) Paste CA TEX Values'!$D$1:$D$96,"ERROR",0,1) -> Fort Bragg | H5: Noyo River Harbor | I5: =IF($J5<K5,"Forecast Amplitude below NTWC Advisory Threshold, refer to Evacuation Playbook",IF(AND($J5>=K5,$J5<L5),"Maritime Response Plan A",IF(AND($J5>=L5,$J5<M5),"Maritime Response Plan B",IF(AND($J5>=M5,$J5<N5),"Maritime Response Plan C",IF(AND($J5>=N5,$J5<O5),"Maritime Response Plan D",IF(AND($J5>=O5,$J5<P5),"Maritime Response Plan E","Maritime Response Plan F")))))) -> Maritime Response Plan E | J5: =_xlfn.XLOOKUP($F5,'(1) Paste CA TEX Values'!$C$1:$C$96,'(1) Paste CA TEX Values'!$I$1:$I$96,"ERROR",0,1) -> 3.2598899 | K5: 0.3 | L5: 0.65 | M5: 0.95 | N5: 1.55 | O5: 1.75 | P5: 4.5
A6: C04-SON-M01 | B6: Bodega | C6: =IF(H6=B6, "-", "ERROR") -> ERROR | D6: Sonoma | E6: 9415020 | F6: BBY | G6: =_xlfn.XLOOKUP($F6,'(1) Paste CA TEX Values'!$C$1:$C$96,'(1) Paste CA TEX Values'!$D$1:$D$96,"ERROR",0,1) -> Bodega Bay | H6: Bodega Bay | I6: =IF($J6<K6,"Forecast Amplitude below NTWC Advisory Threshold, refer to Evacuation Playbook",IF(AND($J6>=K6,$J6<L6),"Maritime Response Plan A",IF(AND($J6>=L6,$J6<M6),"Maritime Response Plan B",IF(AND($J6>=M6,$J6<N6),"Maritime Response Plan C",IF(AND($J6>=N6,$J6<O6),"Maritime Response Plan D",IF(AND($J6>=O6,$J6<P6),"Maritime Response Plan E","Maritime Response Plan F")))))) -> Maritime Response Plan E | J6: =_xlfn.XLOOKUP($F6,'(1) Paste CA TEX Values'!$C$1:$C$96,'(1) Paste CA TEX Values'!$I$1:$I$96,"ERROR",0,1) -> 3.5963077 | K6: 0.3 | L6: 0.45 | M6: 0.65 | N6: 0.75 | O6: 0.85 | P6: NA
A7: C05-MRN-M01 | B7: Richardson Bay | C7: =IF(H7=B7, "-", "ERROR") -> - | D7: Marin | E7: 9414290 | F7: SAU | G7: =_xlfn.XLOOKUP($F7,'(1) Paste CA TEX Values'!$C$1:$C$96,'(1) Paste CA TEX Values'!$D$1:$D$96,"ERROR",0,1) -> Sausalito | H7: Richardson Bay | I7: =IF($J7<K7,"Forecast Amplitude below NTWC Advisory Threshold, refer to Evacuation Playbook",IF(AND($J7>=K7,$J7<L7),"Maritime Response Plan A",IF(AND($J7>=L7,$J7<M7),"Maritime Response Plan B",IF(AND($J7>=M7,$J7<N7),"Maritime Response Plan C",IF(AND($J7>=N7,$J7<O7),"Maritime Response Plan D",IF(AND($J7>=O7,$J7<P7),"Maritime Response Plan E","Maritime Response Plan F")))))) -> Maritime Response Plan E | J7: =_xlfn.XLOOKUP($F7,'(1) Paste CA TEX Values'!$C$1:$C$96,'(1) Paste CA TEX Values'!$I$1:$I$96,"ERROR",0,1) -> 1.863594 | K7: 0.3 | L7: 0.55 | M7: 0.75 | N7: 0.85 | O7: 1.05 | P7: NA
A8: C08-CC-M01 | B8: Richmond | C8: =IF(H8=B8, "-", "ERROR") -> ERROR | D8: Contra Costa | E8: 9414863 | F8: RID | G8: =_xlfn.XLOOKUP($F8,'(1) Paste CA TEX Values'!$C$1:$C$96,'(1) Paste CA TEX Values'!$D$1:$D$96,"ERROR",0,1) -> Richmond | H8: Port of Richmond | I8: =IF($J8<K8,"Forecast Amplitude below NTWC Advisory Threshold, refer to Evacuation Playbook",IF(AND($J8>=K8,$J8<L8),"Maritime Response Plan A",IF(AND($J8>=L8,$J8<M8),"Maritime Response Plan B",IF(AND($J8>=M8,$J8<N8),"Maritime Response Plan C",IF(AND($J8>=N8,$J8<O8),"Maritime Response Plan D",IF(AND($J8>=O8,$J8<P8),"Maritime Response Plan E","Maritime Response Plan F")))))) -> Maritime Response Plan E | J8: =_xlfn.XLOOKUP($F8,'(1) Paste CA TEX Values'!$C$1:$C$96,'(1) Paste CA TEX Values'!$I$1:$I$96,"ERROR",0,1) -> 2.5188487 | K8: 0.3 | L8: 0.45 | M8: 0.55 | N8: 0.75 | O8: 0.85 | P8: NA
A9: C09-ALA-M01 | B9: Oakland-Alameda | C9: =IF(H9=B9, "-", "ERROR") -> ERROR | D9: Alameda | E9: 9414863 | F9: RID | G9: =_xlfn.XLOOKUP($F9,'(1) Paste CA TEX Values'!$C$1:$C$96,'(1) Paste CA TEX Values'!$D$1:$D$96,"ERROR",0,1) -> Richmond | H9: Berkeley-Emeryville | I9: =IF($J9<K9,"Forecast Amplitude below NTWC Advisory Threshold, refer to Evacuation Playbook",IF(AND($J9>=K9,$J9<L9),"Maritime Response Plan A",IF(AND($J9>=L9,$J9<M9),"Maritime Response Plan B",IF(AND($J9>=M9,$J9<N9),"Maritime Response Plan C",IF(AND($J9>=N9,$J9<O9),"Maritime Response Plan D",IF(AND($J9>=O9,$J9<P9),"Maritime Response Plan E","Maritime Response Plan F")))))) -> Maritime Response Plan E | J9: =_xlfn.XLOOKUP($F9,'(1) Paste CA TEX Values'!$C$1:$C$96,'(1) Paste CA TEX Values'!$I$1:$I$96,"ERROR",0,1) -> 2.5188487 | K9: 0.3 | L9: 0.45 | M9: 0.55 | N9: 0.65 | O9: 0.75 | P9: NA
A10: C09-ALA-M02 | B10: Berkeley-Emeryville | C10: =IF(H10=B10, "-", "ERROR") -> ERROR | D10: Alameda | E10: 9414750 | F10: OOH | G10: =_xlfn.XLOOKUP($F10,'(1) Paste CA TEX Values'!$C$1:$C$96,'(1) Paste CA TEX Values'!$D$1:$D$96,"ERROR",0,1) -> Oakland Outer Harbor | H10: Oakland-Alameda | I10: =IF($J10<K10,"Forecast Amplitude below NTWC Advisory Threshold, refer to Evacuation Playbook",IF(AND($J10>=K10,$J10<L10),"Maritime Response Plan A",IF(AND($J10>=L10,$J10<M10),"Maritime Response Plan B",IF(AND($J10>=M10,$J10<N10),"Maritime Response Plan C",IF(AND($J10>=N10,$J10<O10),"Maritime Response Plan D",IF(AND($J10>=O10,$J10<P10),"Maritime Response Plan E","Maritime Response Plan F")))))) -> Maritime Response Plan E | J10: =_xlfn.XLOOKUP($F10,'(1) Paste CA TEX Values'!$C$1:$C$96,'(1) Paste CA TEX Values'!$I$1:$I$96,"ERROR",0,1) -> 3.0073641 | K10: 0.3 | L10: 0.45 | M10: 0.55 | N10: 0.85 | O10: 1.05 | P10: NA
A11: C11-SM-M01 | B11: Half Moon Bay | C11: =IF(H11=B11, "-", "ERROR") -> ERROR | D11: San Francisco | E11: 9414290 | F11: SFC | G11: =_xlfn.XLOOKUP($F11,'(1) Paste CA TEX Values'!$C$1:$C$96,'(1) Paste CA TEX Values'!$D$1:$D$96,"ERROR",0,1) -> San Francisco | H11: San Francisco North | I11: =IF($J11<K11,"Forecast Amplitude below NTWC Advisory Threshold, refer to Evacuation Playbook",IF(AND($J11>=K11,$J11<L11),"Maritime Response Plan A",IF(AND($J11>=L11,$J11<M11),"Maritime Response Plan B",IF(AND($J11>=M11,$J11<N11),"Maritime Response Plan C",IF(AND($J11>=N11,$J11<O11),"Maritime Response Plan D",IF(AND($J11>=O11,$J11<P11),"Maritime Response Plan E","Maritime Response Plan F")))))) -> Maritime Response Plan E | J11: =_xlfn.XLOOKUP($F11,'(1) Paste CA TEX Values'!$C$1:$C$96,'(1) Paste CA TEX Values'!$I$1:$I$96,"ERROR",0,1) -> 2.1465626 | K11: 0.3 | L11: 0.55 | M11: 0.75 | N11: 1.05 | O11: 1.25 | P11: NA
A12: C12-SF-M01 | B12: SF North | C12: =IF(H12=B12, "-", "ERROR") -> ERROR | D12: San Francisco | E12: 9414750 | F12: ALA | G12: =_xlfn.XLOOKUP($F12,'(1) Paste CA TEX Values'!$C$1:$C$96,'(1) Paste CA TEX Values'!$D$1:$D$96,"ERROR",0,1) -> Alameda | H12: San Francisco East | I12: =IF($J12<K12,"Forecast Amplitude below NTWC Advisory Threshold, refer to Evacuation Playbook",IF(AND($J12>=K12,$J12<L12),"Maritime Response Plan A",IF(AND($J12>=L12,$J12<M12),"Maritime Response Plan B",IF(AND($J12>=M12,$J12<N12),"Maritime Response Plan C",IF(AND($J12>=N12,$J12<O12),"Maritime Response Plan D",IF(AND($J12>=O12,$J12<P12),"Maritime Response Plan E","Maritime Response Plan F")))))) -> Maritime Response Plan E | J12: =_xlfn.XLOOKUP($F12,'(1) Paste CA TEX Values'!$C$1:$C$96,'(1) Paste CA TEX Values'!$I$1:$I$96,"ERROR",0,1) -> 1.4056515 | K12: 0.3 | L12: 0.45 | M12: 0.65 | N12: 0.85 | O12: 1.15 | P12: NA
A13: C12-SF-M02 | B13: SF East | C13: =IF(H13=B13, "-", "ERROR") -> ERROR | D13: San Mateo | E13: 9414131 | F13: HMB | G13: =_xlfn.XLOOKUP($F13,'(1) Paste CA TEX Values'!$C$1:$C$96,'(1) Paste CA TEX Values'!$D$1:$D$96,"ERROR",0,1) -> Half Moon Bay | H13: Half Moon Bay | I13: =IF($J13<K13,"Forecast Amplitude below NTWC Advisory Threshold, refer to Evacuation Playbook",IF(AND($J13>=K13,$J13<L13),"Maritime Response Plan A",IF(AND($J13>=L13,$J13<M13),"Maritime Response Plan B",IF(AND($J13>=M13,$J13<N13),"Maritime Response Plan C",IF(AND($J13>=N13,$J13<O13),"Maritime Response Plan D",IF(AND($J13>=O13,$J13<P13),"Maritime Response Plan E","Maritime Response Plan F")))))) -> Maritime Response Plan E | J13: =_xlfn.XLOOKUP($F13,'(1) Paste CA TEX Values'!$C$1:$C$96,'(1) Paste CA TEX Values'!$I$1:$I$96,"ERROR",0,1) -> 4.1623739 | K13: 0.3 | L13: 0.65 | M13: 1.05 | N13: 1.25 | O13: 1.55 | P13: NA
A14: C13-SCR-M01 | B14: Santa Cruz | C14: =IF(H14=B14, "-", "ERROR") -> ERROR | D14: Santa Cruz | E14: 9413450 | F14: SCZ | G14: =_xlfn.XLOOKUP($F14,'(1) Paste CA TEX Values'!$C$1:$C$96,'(1) Paste CA TEX Values'!$D$1:$D$96,"ERROR",0,1) -> Santa Cruz | H14: Santa Cruz Harbor | I14: =IF($J14<K14,"Forecast Amplitude below NTWC Advisory Threshold, refer to Evacuation Playbook",IF(AND($J14>=K14,$J14<L14),"Maritime Response Plan A",IF(AND($J14>=L14,$J14<M14),"Maritime Response Plan B",IF(AND($J14>=M14,$J14<N14),"Maritime Response Plan C",IF(AND($J14>=N14,$J14<O14),"Maritime Response Plan D",IF(AND($J14>=O14,$J14<P14),"Maritime Response Plan E","Maritime Response Plan F")))))) -> Maritime Response Plan E | J14: =_xlfn.XLOOKUP($F14,'(1) Paste CA TEX Values'!$C$1:$C$96,'(1) Paste CA TEX Values'!$I$1:$I$96,"ERROR",0,1) -> 3.6779066 | K14: 0.3 | L14: 0.55 | M14: 0.85 | N14: 1.35 | O14: 1.55 | P14: NA
A15: C14-MONT-M01 | B15: Monterey Harbor | C15: =IF(H15=B15, "-", "ERROR") -> ERROR | D15: Monterey | E15: 9413450 | F15: MSL | G15: =_xlfn.XLOOKUP($F15,'(1) Paste CA TEX Values'!$C$1:$C$96,'(1) Paste CA TEX Values'!$D$1:$D$96,"ERROR",0,1) -> Moss Landing | H15: Moss Landing Harbor | I15: =IF($J15<K15,"Forecast Amplitude below NTWC Advisory Threshold, refer to Evacuation Playbook",IF(AND($J15>=K15,$J15<L15),"Maritime Response Plan A",IF(AND($J15>=L15,$J15<M15),"Maritime Response Plan B",IF(AND($J15>=M15,$J15<N15),"Maritime Response Plan C",IF(AND($J15>=N15,$J15<O15),"Maritime Response Plan D",IF(AND($J15>=O15,$J15<P15),"Maritime Response Plan E","Maritime Response Plan F")))))) -> Maritime Response Plan E | J15: =_xlfn.XLOOKUP($F15,'(1) Paste CA TEX Values'!$C$1:$C$96,'(1) Paste CA TEX Values'!$I$1:$I$96,"ERROR",0,1) -> 2.0268696 | K15: 0.3 | L15: 0.65 | M15: 1.05 | N15: 1.25 | O15: 1.45 | P15: NA
A16: C14-MONT-M02 | B16: Moss Landing | C16: =IF(H16=B16, "-", "ERROR") -> ERROR | D16: Monterey | E16: 9413450 | F16: MNT | G16: =_xlfn.XLOOKUP($F16,'(1) Paste CA TEX Values'!$C$1:$C$96,'(1) Paste CA TEX Values'!$D$1:$D$96,"ERROR",0,1) -> Monterey | H16: Monterey Harbor | I16: =IF($J16<K16,"Forecast Amplitude below NTWC Advisory Threshold, refer to Evacuation Playbook",IF(AND($J16>=K16,$J16<L16),"Maritime Response Plan A",IF(AND($J16>=L16,$J16<M16),"Maritime Response Plan B",IF(AND($J16>=M16,$J16<N16),"Maritime Response Plan C",IF(AND($J16>=N16,$J16<O16),"Maritime Response Plan D",IF(AND($J16>=O16,$J16<P16),"Maritime Response Plan E","Maritime Response Plan F")))))) -> Maritime Response Plan E | J16: =_xlfn.XLOOKUP($F16,'(1) Paste CA TEX Values'!$C$1:$C$96,'(1) Paste CA TEX Values'!$I$1:$I$96,"ERROR",0,1) -> 2.4384179 | K16: 0.3 | L16: 0.65 | M16: 1.05 | N16: 1.35 | O16: 1.65 | P16: NA
